[2023-09-04T14:04:20.806+0000] {taskinstance.py:1165} INFO - Dependencies all met for <TaskInstance: xcom_dag.t3 manual__2023-09-04T14:04:17.420026+00:00 [queued]>
[2023-09-04T14:04:20.817+0000] {taskinstance.py:1165} INFO - Dependencies all met for <TaskInstance: xcom_dag.t3 manual__2023-09-04T14:04:17.420026+00:00 [queued]>
[2023-09-04T14:04:20.818+0000] {taskinstance.py:1362} INFO - 
--------------------------------------------------------------------------------
[2023-09-04T14:04:20.818+0000] {taskinstance.py:1363} INFO - Starting attempt 1 of 1
[2023-09-04T14:04:20.818+0000] {taskinstance.py:1364} INFO - 
--------------------------------------------------------------------------------
[2023-09-04T14:04:20.835+0000] {taskinstance.py:1383} INFO - Executing <Task(PythonOperator): t3> on 2023-09-04 14:04:17.420026+00:00
[2023-09-04T14:04:20.839+0000] {standard_task_runner.py:55} INFO - Started process 6215 to run task
[2023-09-04T14:04:20.842+0000] {standard_task_runner.py:82} INFO - Running: ['***', 'tasks', 'run', 'xcom_dag', 't3', 'manual__2023-09-04T14:04:17.420026+00:00', '--job-id', '207', '--raw', '--subdir', 'DAGS_FOLDER/xcom_dag.py', '--cfg-path', '/tmp/tmpybgt150i']
[2023-09-04T14:04:20.842+0000] {standard_task_runner.py:83} INFO - Job 207: Subtask t3
[2023-09-04T14:04:20.899+0000] {task_command.py:376} INFO - Running <TaskInstance: xcom_dag.t3 manual__2023-09-04T14:04:17.420026+00:00 [running]> on host 6f35104e1718
[2023-09-04T14:04:20.965+0000] {taskinstance.py:1592} INFO - Exporting the following env vars:
AIRFLOW_CTX_DAG_OWNER=***
AIRFLOW_CTX_DAG_ID=xcom_dag
AIRFLOW_CTX_TASK_ID=t3
AIRFLOW_CTX_EXECUTION_DATE=2023-09-04T14:04:17.420026+00:00
AIRFLOW_CTX_TRY_NUMBER=1
AIRFLOW_CTX_DAG_RUN_ID=manual__2023-09-04T14:04:17.420026+00:00
[2023-09-04T14:04:20.965+0000] {taskinstance.py:1851} ERROR - Task failed with exception
Traceback (most recent call last):
  File "/home/airflow/.local/lib/python3.7/site-packages/airflow/operators/python.py", line 175, in execute
    return_value = self.execute_callable()
  File "/home/airflow/.local/lib/python3.7/site-packages/airflow/operators/python.py", line 193, in execute_callable
    return self.python_callable(*self.op_args, **self.op_kwargs)
  File "/opt/airflow/dags/xcom_dag.py", line 17, in _t3
    data = context['ti'].xcom_pull(key = key, task_id = 't2')
  File "/home/airflow/.local/lib/python3.7/site-packages/airflow/utils/session.py", line 75, in wrapper
    return func(*args, session=session, **kwargs)
TypeError: xcom_pull() got an unexpected keyword argument 'task_id'
[2023-09-04T14:04:20.973+0000] {taskinstance.py:1406} INFO - Marking task as FAILED. dag_id=xcom_dag, task_id=t3, execution_date=20230904T140417, start_date=20230904T140420, end_date=20230904T140420
[2023-09-04T14:04:20.984+0000] {standard_task_runner.py:105} ERROR - Failed to execute job 207 for task t3 (xcom_pull() got an unexpected keyword argument 'task_id'; 6215)
[2023-09-04T14:04:21.013+0000] {local_task_job.py:164} INFO - Task exited with return code 1
[2023-09-04T14:04:21.042+0000] {local_task_job.py:273} INFO - 0 downstream tasks scheduled from follow-on schedule check
