[2023-09-04T14:01:15.020+0000] {taskinstance.py:1165} INFO - Dependencies all met for <TaskInstance: xcom_dag.t2 manual__2023-09-04T14:01:12.879455+00:00 [queued]>
[2023-09-04T14:01:15.030+0000] {taskinstance.py:1165} INFO - Dependencies all met for <TaskInstance: xcom_dag.t2 manual__2023-09-04T14:01:12.879455+00:00 [queued]>
[2023-09-04T14:01:15.030+0000] {taskinstance.py:1362} INFO - 
--------------------------------------------------------------------------------
[2023-09-04T14:01:15.030+0000] {taskinstance.py:1363} INFO - Starting attempt 1 of 1
[2023-09-04T14:01:15.030+0000] {taskinstance.py:1364} INFO - 
--------------------------------------------------------------------------------
[2023-09-04T14:01:15.046+0000] {taskinstance.py:1383} INFO - Executing <Task(PythonOperator): t2> on 2023-09-04 14:01:12.879455+00:00
[2023-09-04T14:01:15.050+0000] {standard_task_runner.py:55} INFO - Started process 6065 to run task
[2023-09-04T14:01:15.053+0000] {standard_task_runner.py:82} INFO - Running: ['***', 'tasks', 'run', 'xcom_dag', 't2', 'manual__2023-09-04T14:01:12.879455+00:00', '--job-id', '204', '--raw', '--subdir', 'DAGS_FOLDER/xcom_dag.py', '--cfg-path', '/tmp/tmpfm576k_7']
[2023-09-04T14:01:15.054+0000] {standard_task_runner.py:83} INFO - Job 204: Subtask t2
[2023-09-04T14:01:15.112+0000] {task_command.py:376} INFO - Running <TaskInstance: xcom_dag.t2 manual__2023-09-04T14:01:12.879455+00:00 [running]> on host 6f35104e1718
[2023-09-04T14:01:15.182+0000] {taskinstance.py:1592} INFO - Exporting the following env vars:
AIRFLOW_CTX_DAG_OWNER=***
AIRFLOW_CTX_DAG_ID=xcom_dag
AIRFLOW_CTX_TASK_ID=t2
AIRFLOW_CTX_EXECUTION_DATE=2023-09-04T14:01:12.879455+00:00
AIRFLOW_CTX_TRY_NUMBER=1
AIRFLOW_CTX_DAG_RUN_ID=manual__2023-09-04T14:01:12.879455+00:00
[2023-09-04T14:01:15.183+0000] {taskinstance.py:1851} ERROR - Task failed with exception
Traceback (most recent call last):
  File "/home/airflow/.local/lib/python3.7/site-packages/airflow/operators/python.py", line 175, in execute
    return_value = self.execute_callable()
  File "/home/airflow/.local/lib/python3.7/site-packages/airflow/operators/python.py", line 193, in execute_callable
    return self.python_callable(*self.op_args, **self.op_kwargs)
  File "/opt/airflow/dags/xcom_dag.py", line 13, in _t2
    context['ti'].xcom_push(key = key, val = value)
  File "/home/airflow/.local/lib/python3.7/site-packages/airflow/utils/session.py", line 75, in wrapper
    return func(*args, session=session, **kwargs)
TypeError: xcom_push() got an unexpected keyword argument 'val'
[2023-09-04T14:01:15.191+0000] {taskinstance.py:1406} INFO - Marking task as FAILED. dag_id=xcom_dag, task_id=t2, execution_date=20230904T140112, start_date=20230904T140115, end_date=20230904T140115
[2023-09-04T14:01:15.204+0000] {standard_task_runner.py:105} ERROR - Failed to execute job 204 for task t2 (xcom_push() got an unexpected keyword argument 'val'; 6065)
[2023-09-04T14:01:15.225+0000] {local_task_job.py:164} INFO - Task exited with return code 1
[2023-09-04T14:01:15.258+0000] {local_task_job.py:273} INFO - 0 downstream tasks scheduled from follow-on schedule check
